Workbook
Name bCant: Base_Dashboard!$J$2:$J$397
Name bCat: Base_Dashboard!$F$2:$F$397
Name bCiu: Base_Dashboard!$I$2:$I$397
Name bCosto: Base_Dashboard!$M$2:$M$397
Name bDesv: Base_Dashboard!$O$2:$O$397
Name bMargen: Base_Dashboard!$N$2:$N$397
Name bMes: Base_Dashboard!$C$2:$C$397
Name bMonto: Base_Dashboard!$L$2:$L$397
Name bSeg: Base_Dashboard!$H$2:$H$397
Name bVis: Base_Dashboard!$P$2:$P$397
Name Margen_Neto: Simulación_Escenarios!$C$16
Name Margen_Neto_Pct: Simulación_Escenarios!$C$17
Name Tasa_Costo: Simulación_Escenarios!$C$6

Sheet Dashboard
B2: Dashboard Ejecutivo de Ventas · Productos para Mascotas · Mendoza 2026 | AW2: Proyecto BI Integrador · Javier Linares
B3: =Calc_Dashboard!B110 -> Vista actual: 9 de 9 meses · 5 de 5 categorías · 4 de 4 segmentos · 7 de 7 ciudades | AW3: ="Fuente: tblVentasHechos · "&COUNT(Datos_Ventas!A2:A397)&" ventas · Ene–Sep 2026" -> Fuente: tblVentasHechos · 396 ventas · Ene–Sep 2026
K6: VENTAS TOTALES | V6: MARGEN BRUTO % | AG6: MARGEN NETO % (EST.) | AR6: CRECIMIENTO VS MES ANTERIOR | BC6: UNIDADES VENDIDAS
K7: =Calc_Dashboard!B3 -> 53694490 | V7: =Calc_Dashboard!B6 -> 0.38570047 | AG7: =Calc_Dashboard!B13 -> 0.16499033 | AR7: =Calc_Dashboard!B126 -> 0.079837446 | BC7: =Calc_Dashboard!B15 -> 8371
K8: =Calc_Dashboard!B117 -> Ticket $135,6 mil · 396 ventas | V8: =Calc_Dashboard!B118 -> Margen bruto $20,7 M · costo 61,4% | AG8: =Calc_Dashboard!B119 -> Margen neto $8,9 M · opex 15% | AR8: =Calc_Dashboard!B120 -> Sep vs Ago (último mes visible) | BC8: =Calc_Dashboard!B121 -> 21,1 u. por venta · 7 ciudades
K9: Suma de Monto de las ventas filtradas | V9: Costo según Productos[Costo_Unitario] | AG9: Opex e impuesto de Simulación_Escenarios | AR9: YoY n/d: el modelo no tiene datos 2025 | BC9: Unidades de las ventas filtradas
K49: NOTAS DE ANÁLISIS · hipótesis de negocio contrastadas con IA y validadas con los datos (detalle en la hoja oculta Análisis_IA)
K50: 1 · Mix de producto y margen | AM50: 2 · Política de precios y descuentos
K51: =Calc_Dashboard!B122 -> Alimentos concentra el 53% de las ventas con margen de 33,4% vs 44,4% del resto. Hipótesis (IA): efecto mix. La categoría de mayor volumen compite por precio y su costo depende del proveedor, así que crecer ahí diluye el margen total. Acción: combos con categorías de mayor margen y renegociar costos de compra. | AM51: =Calc_Dashboard!B123 -> Correlación cantidad–precio r = 0,02: el descuento no depende del volumen. Pedidos de menos de 10 u. pagan en promedio 0,0% vs lista y los de 30+ u. 0,0%. Hipótesis (IA): descuentos discrecionales por vendedor o cliente, no una política por volumen. Acción: escala de descuentos por cantidad y aprobación para rebajas mayores al 5%.
K53: 3 · Margen por zona geográfica | AM53: 4 · Estacionalidad de la demanda
K54: =Calc_Dashboard!B124 -> Mendoza factura el 35% del total con margen de 37,1% (promedio 38,6%). Hipótesis (IA): más competencia urbana o clientes con más poder de negociación. Validación: los descuentos son similares entre ciudades; la brecha se explica por el mix (más Alimentos). Acción: impulsar categorías de mayor margen por zona; referencia: Maipú (40,5%). | AM54: =Calc_Dashboard!B125 -> Pico en Mar ($7,9 M) y valle en Abr ($3,7 M, -53% vs pico). Hipótesis (IA): compras de reposición concentradas; el valle se explica por menos transacciones, no por menos días. Acción: planificar stock y promociones antes del valle y revisar el patrón por segmento con los filtros.
B56: Cómo funciona: los segmentadores filtran la tabla oculta tblBaseDash; su columna Visible = SUBTOTAL(103,…) alimenta Calc_Dashboard, por eso KPIs, gráficos, títulos y notas se recalculan con cada filtro.

Sheet Estado_del_Proyecto
B2: Proyecto BI Integrador · Estado de cada requisito
B5: Requisito | C5: Estado | D5: Dónde está
B6: Paso 1 · Consulta Power Query con limpieza (tipos, nulos) | C6: Incluida como conexión (revisar en Excel) | D6: Datos → Consultas y conexiones · código en la hoja Código_M
B7: Paso 1 · Paso renombrado (VentasFiltradas) + comentario // | C7: Incluido en el Editor avanzado de VentasHechos | D7: Consulta VentasHechos
B8: Paso 2 · Modelo de datos, estrella y relaciones 1:N | C8: Pendiente en Excel (diseño en Esquema_Estrella) | D8: Guía_Pasos, Paso 2
B9: Paso 3 · Medida DAX con VAR / RETURN | C9: Código listo; crear en Power Pivot | D9: Hoja Medidas_DAX
B10: Paso 4 · Estadística descriptiva | C10: Hoja incluida (fórmulas equivalentes) | D10: Estadística_Descriptiva
B11: Paso 4 · Administrador de escenarios (3 versiones) | C11: Incluido (nativo de Excel) | D11: Simulación_Escenarios
B12: Paso 4 · Resumen de escenarios | C12: Hoja incluida (réplica con valores) | D12: Resumen_Escenarios
B13: Checkpoint · Dashboard con layout, KPIs y paleta de 3 colores | C13: Incluido | D13: Hoja Dashboard (primera pestaña)
B14: Checkpoint · 4 segmentadores conectados a todos los gráficos | C14: Incluido (segmentadores de tabla sobre tblBaseDash) | D14: Dashboard · columna izquierda
B15: Checkpoint · Cascada, dispersión y storytelling dinámico | C15: Incluido | D15: Dashboard · títulos y textos ligados a Calc_Dashboard
B16: Checkpoint · Análisis asistido por IA | C16: Incluido (completar respuesta textual de ChatGPT) | D16: Hoja oculta Análisis_IA

Sheet Esquema_Estrella
B2: Esquema en Estrella · Vista de diagrama del modelo
B24: RELACIONES (todas 1:N, dirección de filtro única hacia VentasHechos)
B25: Calendario[Fecha] (1) | C25: → | D25: VentasHechos[Fecha] (N)
B26: Clientes[ID_Cliente] (1) | C26: → | D26: VentasHechos[ID_Cliente] (N)
B27: Productos[ID_Producto] (1) | C27: → | D27: VentasHechos[ID_Producto] (N)

Sheet Medidas_DAX
B2: Medidas DAX
B3: Total Ventas := SUM ( VentasHechos[Monto] )
B6: Costo Total :=
B7: SUMX (
B8: VentasHechos,
B9: VentasHechos[Cantidad] * RELATED ( Productos[Costo_Unitario] )
B10: )
B13: Margen Neto :=
B14: VAR VentasTotales = [Total Ventas]
B15: VAR CostoTotal = [Costo Total]
B16: VAR Margen = VentasTotales - CostoTotal
B17: RETURN
... B29: VALORES DE CONTROL (fórmulas de Excel equivalentes a las medidas; deben coincidir con las medidas DAX)
B30: Total Ventas | C30: =SUM(Datos_Ventas!$G$2:$G$397) -> 53694490
B31: Costo Total | C31: =SUMPRODUCT(Datos_Ventas!$E$2:$E$397,SUMIF(Productos!$A$2:$A$11,Datos_Ventas!$D$2:$D$397,Productos!$D$2:$D$11)) -> 32984500
B32: Margen Neto | C32: =C30-C31 -> 20709990
B33: Margen Neto % | C33: =C32/C30 -> 0.38570047

Sheet Datos_Ventas
A1: ID_Venta | B1: Fecha | C1: ID_Cliente | D1: ID_Producto | E1: Cantidad | F1: Precio_Unitario | G1: Monto
A2: 1 | B2: 46023 | C2: C007 | D2: P02 | E2: 21 | F2: 19090 | G2: 400890
A3: 2 | B3: 46023 | C3: C004 | D3: P03 | E3: 8 | F3: 2990 | G3: 23920
A4: 3 | B4: 46024 | C4: C008 | D4: P07 | E4: 22 | F4: 3850 | G4: 84700
A5: 4 | B5: 46024 | C5: C002 | D5: P03 | E5: 30 | F5: 2980 | G5: 89400
A6: 5 | B6: 46024 | C6: C008 | D6: P02 | E6: 13 | F6: 17890 | G6: 232570
A7: 6 | B7: 46024 | C7: C008 | D7: P03 | E7: 8 | F7: 3320 | G7: 26560
A8: 7 | B8: 46025 | C8: C004 | D8: P04 | E8: 11 | F8: 2860 | G8: 31460
A9: 8 | B9: 46025 | C9: C002 | D9: P10 | E9: 24 | F9: 5270 | G9: 126480
A10: 9 | B10: 46025 | C10: C010 | D10: P05 | E10: 6 | F10: 4200 | G10: 25200
A11: 10 | B11: 46026 | C11: C008 | D11: P08 | E11: 20 | F11: 5390 | G11: 107800
A12: 11 | B12: 46027 | C12: C008 | D12: P03 | E12: 20 | F12: 2960 | G12: 59200
A13: 12 | B13: 46027 | C13: C010 | D13: P10 | E13: 13 | F13: 5350 | G13: 69550
... A397: 420 | B397: 46293 | C397: C002 | D397: P03 | E397: 20 | F397: 2970 | G397: 59400

Sheet Datos_Crudos
A1: ID_Venta | B1: Fecha | C1: ID_Cliente | D1: ID_Producto | E1: Cantidad | F1: Precio_Unitario | G1: Monto
A2: 1 | B2: 01/01/2026 | C2: C007 | D2: P02 | E2: 21 | F2: 19090 | G2: 400890
A3: 2 | B3: 01/01/2026 | C3: C004 | D3: P03 | E3: 8 | F3: 2990 | G3: 23920
A4: 3 | B4: 02/01/2026 | C4: C008 | D4: P07 | E4: 22 | F4: 3850 | G4: 84700
A5: 4 | B5: 02/01/2026 | C5: C002 | D5: P03 | E5: 30 | F5: 2980 | G5: 89400
A6: 5 | B6: 02/01/2026 | C6: C008 | D6: P02 | E6: 13 | F6: 17890 | G6: 232570
A7: 6 | B7: 02/01/2026 | C7: C008 | D7: P03 | E7: 8 | F7: 3320 | G7: 26560
A8: 7 | B8: 03/01/2026 | C8: C004 | D8: P04 | E8: 11 | F8: 2860 | G8: 31460
A9: 8 | B9: 03/01/2026 | C9: C002 | D9: P10 | E9: 24 | F9: 5270 | G9: 126480
A10: 9 | B10: 03/01/2026 | C10: C010 | D10: P05 | E10: 6 | F10: 4200 | G10: 25200
A11: 10 | B11: 04/01/2026 | C11: C008 | D11: P08 | E11: 20 | F11: 5390 | G11: 107800
A12: 11 | B12: 05/01/2026 | C12: C008 | D12: P03 | E12: 20 | F12: 2960 | G12: 59200
A13: 12 | B13: 05/01/2026 | C13: C010 | D13: P10 | E13: 13 | F13: 5350 | G13: 69550
... A18: 17 | B18: 08/01/2026 | C18: C003 | D18: P10 | E18: 32 | F18: 5730 | G18: 183360
A19: 18 | C19: C005 | D19: P01 | E19: 36 | F19: 13720 | G19: 493920
A20: 19 | B20: 09/01/2026 | C20: C004 | D20: P08 | E20: 19 | F20: 4870 | G20: 92530
A21: 20 | B21: 10/01/2026 | C21: C001 | D21: P07 | E21: 18 | F21: 3370 | G21: 60660
A22: 21 | B22: 10/01/2026 | C22: C008 | D22: P06 | E22: 39 | F22: 3870 | G22: 150930
A23: 22 | B23: 11/01/2026 | C23: C005 | D23: P09 | E23: 30 | F23: 1930 | G23: 57900
A24: 23 | B24: 11/01/2026 | C24: C009 | D24: P05 | E24: 29 | F24: 4360 | G24: 126440
A25: 24 | B25: 12/01/2026 | C25: C008 | D25: P08 | E25: 10 | F25: 4880 | G25: 48800
A26: 25 | B26: 13/01/2026 | C26: C005 | D26: P07 | E26: 11 | F26: 3670 | G26: 40370
A27: 26 | B27: 14/01/2026 | C27: C002 | D27: P09 | E27: 20 | F27: 1680 | G27: 33600
A28: 27 | B28: 15/01/2026 | C28: C001 | D28: P02 | E28: 4 | F28: 20310 | G28: 81240
A29: 28 | B29: 16/01/2026 | C29: C009 | D29: P07 | E29: 4 | F29: 3800 | G29: 15200
A30: 29 | B30: 16/01/2026 | C30: C001 | D30: P03 | E30: 28 | F30: 2980 | G30: 83440
A31: 30 | B31: 16/01/2026 | C31: C001 | D31: P02 | E31: 40 | F31: 18610 | G31: 744400
... A58: 57 | B58: 07/02/2026 | C58: C003 | D58: P05 | E58: 7 | F58: 4430 | G58: 31010
A59: 58 | B59: 07/02/2026 | C59: C007 | D59: P05 | E59: 27 | F59: 4110
A60: 59 | B60: 09/02/2026 | C60: C003 | D60: P02 | E60: 27 | F60: 19700 | G60: 531900
A61: 60 | B61: 09/02/2026 | C61: C008 | D61: P01 | E61: 14 | F61: 14560 | G61: 203840
A62: 61 | B62: 10/02/2026 | C62: C010 | D62: P07 | E62: 24 | F62: 3700 | G62: 88800
A63: 62 | B63: 10/02/2026 | C63: C010 | D63: P03 | E63: 38 | F63: 3180 | G63: 120840
A64: 63 | B64: 12/02/2026 | C64: C004 | D64: P07 | E64: 35 | F64: 3580 | G64: 125300
A65: 64 | B65: 12/02/2026 | C65: C001 | D65: P03 | E65: 24 | F65: 3350 | G65: 80400
A66: 65 | B66: 14/02/2026 | C66: C006 | D66: P10 | E66: 38 | F66: 5920 | G66: 224960
A67: 66 | B67: 14/02/2026 | C67: C002 | D67: P02 | E67: 22 | F67: 17670 | G67: 388740
A68: 67 | B68: 15/02/2026 | C68: C003 | D68: P06 | E68: 6 | F68: 3980 | G68: 23880
A69: 68 | B69: 15/02/2026 | C69: C008 | D69: P05 | E69: 40 | F69: 4370 | G69: 174800
A70: 69 | B70: 15/02/2026 | C70: C003 | D70: P04 | E70: 26 | F70: 2480 | G70: 64480
...

Sheet Clientes
A1: ID_Cliente | B1: Cliente | C1: Segmento | D1: Ciudad
A2: C001 | B2: Distribuidora Andes | C2: Mayorista | D2: Mendoza
A3: C002 | B3: Kiosco La Esquina | C3: Minorista | D3: Godoy Cruz
A4: C003 | B4: Supermercado Cuyo | C4: Retail | D4: Guaymallén
A5: C004 | B5: Almacén Don Pedro | C5: Minorista | D5: Maipú
A6: C005 | B6: Hiper Centro | C6: Retail | D6: Luján de Cuyo
A7: C006 | B7: Mayorista del Sol | C7: Mayorista | D7: San Martín
A8: C007 | B8: Despensa Vero | C8: Minorista | D8: Mendoza
A9: C008 | B9: Autoservicio Norte | C9: Retail | D9: Las Heras
A10: C009 | B10: Pet Shop Mascotas | C10: Especializado | D10: Mendoza
A11: C010 | B11: Veterinaria Sur | C11: Especializado | D11: Godoy Cruz

Sheet Productos
A1: ID_Producto | B1: Producto | C1: Categoría | D1: Costo_Unitario | E1: Precio_Lista
A2: P01 | B2: Alimento Balanceado 15kg | C2: Alimentos | D2: 9800 | E2: 14500
A3: P02 | B3: Alimento Premium 10kg | C3: Alimentos | D3: 12500 | E3: 18900
A4: P03 | B4: Snack Dental | C4: Snacks | D4: 1800 | E4: 3200
A5: P04 | B5: Galletas Perro | C5: Snacks | D5: 1500 | E5: 2700
A6: P05 | B6: Arena Sanitaria | C6: Higiene | D6: 2600 | E6: 4400
A7: P06 | B7: Shampoo Mascotas | C7: Higiene | D7: 2200 | E7: 3900
A8: P07 | B8: Collar Ajustable | C8: Accesorios | D8: 1900 | E8: 3600
A9: P08 | B9: Correa Reforzada | C9: Accesorios | D9: 2800 | E9: 5200
A10: P09 | B10: Juguete Pelota | C10: Accesorios | D10: 900 | E10: 1800
A11: P10 | B11: Aceite Omega | C11: Suplementos | D11: 3100 | E11: 5600

Sheet Calendario
A1: Fecha | B1: Año | C1: N° Mes | D1: Mes | E1: Trimestre
A2: 46023 | B2: 2026 | C2: 1 | D2: Enero | E2: T1
A3: 46024 | B3: 2026 | C3: 1 | D3: Enero | E3: T1
A4: 46025 | B4: 2026 | C4: 1 | D4: Enero | E4: T1
A5: 46026 | B5: 2026 | C5: 1 | D5: Enero | E5: T1
A6: 46027 | B6: 2026 | C6: 1 | D6: Enero | E6: T1
A7: 46028 | B7: 2026 | C7: 1 | D7: Enero | E7: T1
A8: 46029 | B8: 2026 | C8: 1 | D8: Enero | E8: T1
A9: 46030 | B9: 2026 | C9: 1 | D9: Enero | E9: T1
A10: 46031 | B10: 2026 | C10: 1 | D10: Enero | E10: T1
A11: 46032 | B11: 2026 | C11: 1 | D11: Enero | E11: T1
A12: 46033 | B12: 2026 | C12: 1 | D12: Enero | E12: T1
A13: 46034 | B13: 2026 | C13: 1 | D13: Enero | E13: T1
... A366: 46387 | B366: 2026 | C366: 12 | D366: Diciembre | E366: T4

Sheet Estadística_Descriptiva
B2: Estadística Descriptiva · Monto de ventas
B5: Variable | C5: Monto
B6: Media | C6: =AVERAGE(Datos_Ventas!$G$2:$G$397) -> 135592.15
B7: Error típico | C7: =_xlfn.STDEV.S(Datos_Ventas!$G$2:$G$397)/SQRT(COUNT(Datos_Ventas!$G$2:$G$397)) -> 7368.4862
B8: Mediana | C8: =MEDIAN(Datos_Ventas!$G$2:$G$397) -> 89765
B9: Moda | C9: =IFERROR(_xlfn.MODE.SNGL(Datos_Ventas!$G$2:$G$397),"n/d") -> 25200
B10: Desviación estándar | C10: =_xlfn.STDEV.S(Datos_Ventas!$G$2:$G$397) -> 146631.02
B11: Varianza de la muestra | C11: =_xlfn.VAR.S(Datos_Ventas!$G$2:$G$397) -> 2.1500657e+10
B12: Curtosis | C12: =KURT(Datos_Ventas!$G$2:$G$397) -> 4.7051709
B13: Coeficiente de asimetría | C13: =SKEW(Datos_Ventas!$G$2:$G$397) -> 2.1703937
B14: Rango | C14: =MAX(Datos_Ventas!$G$2:$G$397)-MIN(Datos_Ventas!$G$2:$G$397) -> 744790
B15: Mínimo | C15: =MIN(Datos_Ventas!$G$2:$G$397) -> 1910
B16: Máximo | C16: =MAX(Datos_Ventas!$G$2:$G$397) -> 746700
B17: Suma | C17: =SUM(Datos_Ventas!$G$2:$G$397) -> 53694490
B18: Cuenta | C18: =COUNT(Datos_Ventas!$G$2:$G$397) -> 396
B19: Nivel de confianza(95,0%) | C19: =_xlfn.CONFIDENCE.T(0.05,_xlfn.STDEV.S(Datos_Ventas!$G$2:$G$397),COUNT(Datos_Ventas!$G$2:$G$397)) -> 14486.354

Sheet Simulación_Escenarios
B2: Simulación de Escenarios
B4: SUPUESTOS
B5: Ventas totales (suma de Monto) | C5: =SUM(Datos_Ventas!$G$2:$G$397) -> 53694490
B6: Tasa de costo (% de ventas) | C6: 0.6
B7: Gastos operativos (% de ventas) | C7: 0.15
B8: Tasa de impuesto | C8: 0.3
B10: RESULTADOS
B11: Costo de ventas | C11: =C5*C6 -> 32216694
B12: Utilidad bruta | C12: =C5-C11 -> 21477796
B13: Gastos operativos | C13: =C5*C7 -> 8054173.5
B14: Utilidad antes de impuestos | C14: =C12-C13 -> 13423622
B15: Impuesto | C15: =MAX(0,C14)*C8 -> 4027086.8
B16: Margen neto ($) | C16: =C14-C15 -> 9396535.8
B17: Margen neto (%) | C17: =C16/C5 -> 0.175

Sheet Resumen_Escenarios
B2: Resumen de escenarios
D4: Valores actuales: | E4: Pesimista | F4: Base | G4: Optimista
B5: Celdas cambiantes:
C6: Tasa_Costo | D6: 0.6 | E6: 0.72 | F6: 0.6 | G6: 0.5
B8: Celdas de resultado:
C9: Margen_Neto | D9: 9396535.8 | E9: 4886198.6 | F9: 9396535.8 | G9: 13155150
C10: Margen_Neto_Pct | D10: 0.175 | E10: 0.091 | F10: 0.175 | G10: 0.245

Sheet Base_Dashboard
A1: ID_Venta | B1: Fecha | C1: Mes | D1: Trimestre | E1: Producto | F1: Categoría | G1: Cliente | H1: Segmento | I1: Ciudad | J1: Cantidad | K1: Precio_Unitario | L1: Monto | M1: Costo | N1: Margen | O1: Desvío_Precio | P1: Visible
A2: =Datos_Ventas!A2 -> 1 | B2: =Datos_Ventas!B2 -> 46023 | C2: =CHOOSE(MONTH(B2),"01 Ene","02 Feb","03 Mar","04 Abr","05 May","06 Jun","07 Jul","08 Ago","09 Sep","10 Oct","11 Nov","12 Dic") -> 01 Ene | D2: ="T"&ROUNDUP(MONTH(B2)/3,0) -> T1 | E2: =INDEX(Productos!$B$2:$B$11,MATCH(Datos_Ventas!D2,Productos!$A$2:$A$11,0)) -> Alimento Premium 10kg | F2: =INDEX(Productos!$C$2:$C$11,MATCH(Datos_Ventas!D2,Productos!$A$2:$A$11,0)) -> Alimentos | G2: =INDEX(Clientes!$B$2:$B$11,MATCH(Datos_Ventas!C2,Clientes!$A$2:$A$11,0)) -> Despensa Vero | H2: =INDEX(Clientes!$C$2:$C$11,MATCH(Datos_Ventas!C2,Clientes!$A$2:$A$11,0)) -> Minorista | I2: =INDEX(Clientes!$D$2:$D$11,MATCH(Datos_Ventas!C2,Clientes!$A$2:$A$11,0)) -> Mendoza | J2: =Datos_Ventas!E2 -> 21 | K2: =Datos_Ventas!F2 -> 19090 | L2: =Datos_Ventas!G2 -> 400890 | M2: =J2*INDEX(Productos!$D$2:$D$11,MATCH(Datos_Ventas!D2,Productos!$A$2:$A$11,0)) -> 262500 | N2: =L2-M2 -> 138390 | O2: =K2/INDEX(Productos!$E$2:$E$11,MATCH(Datos_Ventas!D2,Productos!$A$2:$A$11,0))-1 -> 0.01005291 | P2: =SUBTOTAL(103,A2) -> 1
A3: =Datos_Ventas!A3 -> 2 | B3: =Datos_Ventas!B3 -> 46023 | C3: =CHOOSE(MONTH(B3),"01 Ene","02 Feb","03 Mar","04 Abr","05 May","06 Jun","07 Jul","08 Ago","09 Sep","10 Oct","11 Nov","12 Dic") -> 01 Ene | D3: ="T"&ROUNDUP(MONTH(B3)/3,0) -> T1 | E3: =INDEX(Productos!$B$2:$B$11,MATCH(Datos_Ventas!D3,Productos!$A$2:$A$11,0)) -> Snack Dental | F3: =INDEX(Productos!$C$2:$C$11,MATCH(Datos_Ventas!D3,Productos!$A$2:$A$11,0)) -> Snacks | G3: =INDEX(Clientes!$B$2:$B$11,MATCH(Datos_Ventas!C3,Clientes!$A$2:$A$11,0)) -> Almacén Don Pedro | H3: =INDEX(Clientes!$C$2:$C$11,MATCH(Datos_Ventas!C3,Clientes!$A$2:$A$11,0)) -> Minorista | I3: =INDEX(Clientes!$D$2:$D$11,MATCH(Datos_Ventas!C3,Clientes!$A$2:$A$11,0)) -> Maipú | J3: =Datos_Ventas!E3 -> 8 | K3: =Datos_Ventas!F3 -> 2990 | L3: =Datos_Ventas!G3 -> 23920 | M3: =J3*INDEX(Productos!$D$2:$D$11,MATCH(Datos_Ventas!D3,Productos!$A$2:$A$11,0)) -> 14400 | N3: =L3-M3 -> 9520 | O3: =K3/INDEX(Productos!$E$2:$E$11,MATCH(Datos_Ventas!D3,Productos!$A$2:$A$11,0))-1 -> -0.065625 | P3: =SUBTOTAL(103,A3) -> 1
A4: =Datos_Ventas!A4 -> 3 | B4: =Datos_Ventas!B4 -> 46024 | C4: =CHOOSE(MONTH(B4),"01 Ene","02 Feb","03 Mar","04 Abr","05 May","06 Jun","07 Jul","08 Ago","09 Sep","10 Oct","11 Nov","12 Dic") -> 01 Ene | D4: ="T"&ROUNDUP(MONTH(B4)/3,0) -> T1 | E4: =INDEX(Productos!$B$2:$B$11,MATCH(Datos_Ventas!D4,Productos!$A$2:$A$11,0)) -> Collar Ajustable | F4: =INDEX(Productos!$C$2:$C$11,MATCH(Datos_Ventas!D4,Productos!$A$2:$A$11,0)) -> Accesorios | G4: =INDEX(Clientes!$B$2:$B$11,MATCH(Datos_Ventas!C4,Clientes!$A$2:$A$11,0)) -> Autoservicio Norte | H4: =INDEX(Clientes!$C$2:$C$11,MATCH(Datos_Ventas!C4,Clientes!$A$2:$A$11,0)) -> Retail | I4: =INDEX(Clientes!$D$2:$D$11,MATCH(Datos_Ventas!C4,Clientes!$A$2:$A$11,0)) -> Las Heras | J4: =Datos_Ventas!E4 -> 22 | K4: =Datos_Ventas!F4 -> 3850 | L4: =Datos_Ventas!G4 -> 84700 | M4: =J4*INDEX(Productos!$D$2:$D$11,MATCH(Datos_Ventas!D4,Productos!$A$2:$A$11,0)) -> 41800 | N4: =L4-M4 -> 42900 | O4: =K4/INDEX(Productos!$E$2:$E$11,MATCH(Datos_Ventas!D4,Productos!$A$2:$A$11,0))-1 -> 0.069444444 | P4: =SUBTOTAL(103,A4) -> 1
A5: =Datos_Ventas!A5 -> 4 | B5: =Datos_Ventas!B5 -> 46024 | C5: =CHOOSE(MONTH(B5),"01 Ene","02 Feb","03 Mar","04 Abr","05 May","06 Jun","07 Jul","08 Ago","09 Sep","10 Oct","11 Nov","12 Dic") -> 01 Ene | D5: ="T"&ROUNDUP(MONTH(B5)/3,0) -> T1 | E5: =INDEX(Productos!$B$2:$B$11,MATCH(Datos_Ventas!D5,Productos!$A$2:$A$11,0)) -> Snack Dental | F5: =INDEX(Productos!$C$2:$C$11,MATCH(Datos_Ventas!D5,Productos!$A$2:$A$11,0)) -> Snacks | G5: =INDEX(Clientes!$B$2:$B$11,MATCH(Datos_Ventas!C5,Clientes!$A$2:$A$11,0)) -> Kiosco La Esquina | H5: =INDEX(Clientes!$C$2:$C$11,MATCH(Datos_Ventas!C5,Clientes!$A$2:$A$11,0)) -> Minorista | I5: =INDEX(Clientes!$D$2:$D$11,MATCH(Datos_Ventas!C5,Clientes!$A$2:$A$11,0)) -> Godoy Cruz | J5: =Datos_Ventas!E5 -> 30 | K5: =Datos_Ventas!F5 -> 2980 | L5: =Datos_Ventas!G5 -> 89400 | M5: =J5*INDEX(Productos!$D$2:$D$11,MATCH(Datos_Ventas!D5,Productos!$A$2:$A$11,0)) -> 54000 | N5: =L5-M5 -> 35400 | O5: =K5/INDEX(Productos!$E$2:$E$11,MATCH(Datos_Ventas!D5,Productos!$A$2:$A$11,0))-1 -> -0.06875 | P5: =SUBTOTAL(103,A5) -> 1
A6: =Datos_Ventas!A6 -> 5 | B6: =Datos_Ventas!B6 -> 46024 | C6: =CHOOSE(MONTH(B6),"01 Ene","02 Feb","03 Mar","04 Abr","05 May","06 Jun","07 Jul","08 Ago","09 Sep","10 Oct","11 Nov","12 Dic") -> 01 Ene | D6: ="T"&ROUNDUP(MONTH(B6)/3,0) -> T1 | E6: =INDEX(Productos!$B$2:$B$11,MATCH(Datos_Ventas!D6,Productos!$A$2:$A$11,0)) -> Alimento Premium 10kg | F6: =INDEX(Productos!$C$2:$C$11,MATCH(Datos_Ventas!D6,Productos!$A$2:$A$11,0)) -> Alimentos | G6: =INDEX(Clientes!$B$2:$B$11,MATCH(Datos_Ventas!C6,Clientes!$A$2:$A$11,0)) -> Autoservicio Norte | H6: =INDEX(Clientes!$C$2:$C$11,MATCH(Datos_Ventas!C6,Clientes!$A$2:$A$11,0)) -> Retail | I6: =INDEX(Clientes!$D$2:$D$11,MATCH(Datos_Ventas!C6,Clientes!$A$2:$A$11,0)) -> Las Heras | J6: =Datos_Ventas!E6 -> 13 | K6: =Datos_Ventas!F6 -> 17890 | L6: =Datos_Ventas!G6 -> 232570 | M6: =J6*INDEX(Productos!$D$2:$D$11,MATCH(Datos_Ventas!D6,Productos!$A$2:$A$11,0)) -> 162500 | N6: =L6-M6 -> 70070 | O6: =K6/INDEX(Productos!$E$2:$E$11,MATCH(Datos_Ventas!D6,Productos!$A$2:$A$11,0))-1 -> -0.053439153 | P6: =SUBTOTAL(103,A6) -> 1
A7: =Datos_Ventas!A7 -> 6 | B7: =Datos_Ventas!B7 -> 46024 | C7: =CHOOSE(MONTH(B7),"01 Ene","02 Feb","03 Mar","04 Abr","05 May","06 Jun","07 Jul","08 Ago","09 Sep","10 Oct","11 Nov","12 Dic") -> 01 Ene | D7: ="T"&ROUNDUP(MONTH(B7)/3,0) -> T1 | E7: =INDEX(Productos!$B$2:$B$11,MATCH(Datos_Ventas!D7,Productos!$A$2:$A$11,0)) -> Snack Dental | F7: =INDEX(Productos!$C$2:$C$11,MATCH(Datos_Ventas!D7,Productos!$A$2:$A$11,0)) -> Snacks | G7: =INDEX(Clientes!$B$2:$B$11,MATCH(Datos_Ventas!C7,Clientes!$A$2:$A$11,0)) -> Autoservicio Norte | H7: =INDEX(Clientes!$C$2:$C$11,MATCH(Datos_Ventas!C7,Clientes!$A$2:$A$11,0)) -> Retail | I7: =INDEX(Clientes!$D$2:$D$11,MATCH(Datos_Ventas!C7,Clientes!$A$2:$A$11,0)) -> Las Heras | J7: =Datos_Ventas!E7 -> 8 | K7: =Datos_Ventas!F7 -> 3320 | L7: =Datos_Ventas!G7 -> 26560 | M7: =J7*INDEX(Productos!$D$2:$D$11,MATCH(Datos_Ventas!D7,Productos!$A$2:$A$11,0)) -> 14400 | N7: =L7-M7 -> 12160 | O7: =K7/INDEX(Productos!$E$2:$E$11,MATCH(Datos_Ventas!D7,Productos!$A$2:$A$11,0))-1 -> 0.0375 | P7: =SUBTOTAL(103,A7) -> 1
A8: =Datos_Ventas!A8 -> 7 | B8: =Datos_Ventas!B8 -> 46025 | C8: =CHOOSE(MONTH(B8),"01 Ene","02 Feb","03 Mar","04 Abr","05 May","06 Jun","07 Jul","08 Ago","09 Sep","10 Oct","11 Nov","12 Dic") -> 01 Ene | D8: ="T"&ROUNDUP(MONTH(B8)/3,0) -> T1 | E8: =INDEX(Productos!$B$2:$B$11,MATCH(Datos_Ventas!D8,Productos!$A$2:$A$11,0)) -> Galletas Perro | F8: =INDEX(Productos!$C$2:$C$11,MATCH(Datos_Ventas!D8,Productos!$A$2:$A$11,0)) -> Snacks | G8: =INDEX(Clientes!$B$2:$B$11,MATCH(Datos_Ventas!C8,Clientes!$A$2:$A$11,0)) -> Almacén Don Pedro | H8: =INDEX(Clientes!$C$2:$C$11,MATCH(Datos_Ventas!C8,Clientes!$A$2:$A$11,0)) -> Minorista | I8: =INDEX(Clientes!$D$2:$D$11,MATCH(Datos_Ventas!C8,Clientes!$A$2:$A$11,0)) -> Maipú | J8: =Datos_Ventas!E8 -> 11 | K8: =Datos_Ventas!F8 -> 2860 | L8: =Datos_Ventas!G8 -> 31460 | M8: =J8*INDEX(Productos!$D$2:$D$11,MATCH(Datos_Ventas!D8,Productos!$A$2:$A$11,0)) -> 16500 | N8: =L8-M8 -> 14960 | O8: =K8/INDEX(Productos!$E$2:$E$11,MATCH(Datos_Ventas!D8,Productos!$A$2:$A$11,0))-1 -> 0.059259259 | P8: =SUBTOTAL(103,A8) -> 1
A9: =Datos_Ventas!A9 -> 8 | B9: =Datos_Ventas!B9 -> 46025 | C9: =CHOOSE(MONTH(B9),"01 Ene","02 Feb","03 Mar","04 Abr","05 May","06 Jun","07 Jul","08 Ago","09 Sep","10 Oct","11 Nov","12 Dic") -> 01 Ene | D9: ="T"&ROUNDUP(MONTH(B9)/3,0) -> T1 | E9: =INDEX(Productos!$B$2:$B$11,MATCH(Datos_Ventas!D9,Productos!$A$2:$A$11,0)) -> Aceite Omega | F9: =INDEX(Productos!$C$2:$C$11,MATCH(Datos_Ventas!D9,Productos!$A$2:$A$11,0)) -> Suplementos | G9: =INDEX(Clientes!$B$2:$B$11,MATCH(Datos_Ventas!C9,Clientes!$A$2:$A$11,0)) -> Kiosco La Esquina | H9: =INDEX(Clientes!$C$2:$C$11,MATCH(Datos_Ventas!C9,Clientes!$A$2:$A$11,0)) -> Minorista | I9: =INDEX(Clientes!$D$2:$D$11,MATCH(Datos_Ventas!C9,Clientes!$A$2:$A$11,0)) -> Godoy Cruz | J9: =Datos_Ventas!E9 -> 24 | K9: =Datos_Ventas!F9 -> 5270 | L9: =Datos_Ventas!G9 -> 126480 | M9: =J9*INDEX(Productos!$D$2:$D$11,MATCH(Datos_Ventas!D9,Productos!$A$2:$A$11,0)) -> 74400 | N9: =L9-M9 -> 52080 | O9: =K9/INDEX(Productos!$E$2:$E$11,MATCH(Datos_Ventas!D9,Productos!$A$2:$A$11,0))-1 -> -0.058928571 | P9: =SUBTOTAL(103,A9) -> 1
A10: =Datos_Ventas!A10 -> 9 | B10: =Datos_Ventas!B10 -> 46025 | C10: =CHOOSE(MONTH(B10),"01 Ene","02 Feb","03 Mar","04 Abr","05 May","06 Jun","07 Jul","08 Ago","09 Sep","10 Oct","11 Nov","12 Dic") -> 01 Ene | D10: ="T"&ROUNDUP(MONTH(B10)/3,0) -> T1 | E10: =INDEX(Productos!$B$2:$B$11,MATCH(Datos_Ventas!D10,Productos!$A$2:$A$11,0)) -> Arena Sanitaria | F10: =INDEX(Productos!$C$2:$C$11,MATCH(Datos_Ventas!D10,Productos!$A$2:$A$11,0)) -> Higiene | G10: =INDEX(Clientes!$B$2:$B$11,MATCH(Datos_Ventas!C10,Clientes!$A$2:$A$11,0)) -> Veterinaria Sur | H10: =INDEX(Clientes!$C$2:$C$11,MATCH(Datos_Ventas!C10,Clientes!$A$2:$A$11,0)) -> Especializado | I10: =INDEX(Clientes!$D$2:$D$11,MATCH(Datos_Ventas!C10,Clientes!$A$2:$A$11,0)) -> Godoy Cruz | J10: =Datos_Ventas!E10 -> 6 | K10: =Datos_Ventas!F10 -> 4200 | L10: =Datos_Ventas!G10 -> 25200 | M10: =J10*INDEX(Productos!$D$2:$D$11,MATCH(Datos_Ventas!D10,Productos!$A$2:$A$11,0)) -> 15600 | N10: =L10-M10 -> 9600 | O10: =K10/INDEX(Productos!$E$2:$E$11,MATCH(Datos_Ventas!D10,Productos!$A$2:$A$11,0))-1 -> -0.045454545 | P10: =SUBTOTAL(103,A10) -> 1
A11: =Datos_Ventas!A11 -> 10 | B11: =Datos_Ventas!B11 -> 46026 | C11: =CHOOSE(MONTH(B11),"01 Ene","02 Feb","03 Mar","04 Abr","05 May","06 Jun","07 Jul","08 Ago","09 Sep","10 Oct","11 Nov","12 Dic") -> 01 Ene | D11: ="T"&ROUNDUP(MONTH(B11)/3,0) -> T1 | E11: =INDEX(Productos!$B$2:$B$11,MATCH(Datos_Ventas!D11,Productos!$A$2:$A$11,0)) -> Correa Reforzada | F11: =INDEX(Productos!$C$2:$C$11,MATCH(Datos_Ventas!D11,Productos!$A$2:$A$11,0)) -> Accesorios | G11: =INDEX(Clientes!$B$2:$B$11,MATCH(Datos_Ventas!C11,Clientes!$A$2:$A$11,0)) -> Autoservicio Norte | H11: =INDEX(Clientes!$C$2:$C$11,MATCH(Datos_Ventas!C11,Clientes!$A$2:$A$11,0)) -> Retail | I11: =INDEX(Clientes!$D$2:$D$11,MATCH(Datos_Ventas!C11,Clientes!$A$2:$A$11,0)) -> Las Heras | J11: =Datos_Ventas!E11 -> 20 | K11: =Datos_Ventas!F11 -> 5390 | L11: =Datos_Ventas!G11 -> 107800 | M11: =J11*INDEX(Productos!$D$2:$D$11,MATCH(Datos_Ventas!D11,Productos!$A$2:$A$11,0)) -> 56000 | N11: =L11-M11 -> 51800 | O11: =K11/INDEX(Productos!$E$2:$E$11,MATCH(Datos_Ventas!D11,Productos!$A$2:$A$11,0))-1 -> 0.036538462 | P11: =SUBTOTAL(103,A11) -> 1
A12: =Datos_Ventas!A12 -> 11 | B12: =Datos_Ventas!B12 -> 46027 | C12: =CHOOSE(MONTH(B12),"01 Ene","02 Feb","03 Mar","04 Abr","05 May","06 Jun","07 Jul","08 Ago","09 Sep","10 Oct","11 Nov","12 Dic") -> 01 Ene | D12: ="T"&ROUNDUP(MONTH(B12)/3,0) -> T1 | E12: =INDEX(Productos!$B$2:$B$11,MATCH(Datos_Ventas!D12,Productos!$A$2:$A$11,0)) -> Snack Dental | F12: =INDEX(Productos!$C$2:$C$11,MATCH(Datos_Ventas!D12,Productos!$A$2:$A$11,0)) -> Snacks | G12: =INDEX(Clientes!$B$2:$B$11,MATCH(Datos_Ventas!C12,Clientes!$A$2:$A$11,0)) -> Autoservicio Norte | H12: =INDEX(Clientes!$C$2:$C$11,MATCH(Datos_Ventas!C12,Clientes!$A$2:$A$11,0)) -> Retail | I12: =INDEX(Clientes!$D$2:$D$11,MATCH(Datos_Ventas!C12,Clientes!$A$2:$A$11,0)) -> Las Heras | J12: =Datos_Ventas!E12 -> 20 | K12: =Datos_Ventas!F12 -> 2960 | L12: =Datos_Ventas!G12 -> 59200 | M12: =J12*INDEX(Productos!$D$2:$D$11,MATCH(Datos_Ventas!D12,Productos!$A$2:$A$11,0)) -> 36000 | N12: =L12-M12 -> 23200 | O12: =K12/INDEX(Productos!$E$2:$E$11,MATCH(Datos_Ventas!D12,Productos!$A$2:$A$11,0))-1 -> -0.075 | P12: =SUBTOTAL(103,A12) -> 1
A13: =Datos_Ventas!A13 -> 12 | B13: =Datos_Ventas!B13 -> 46027 | C13: =CHOOSE(MONTH(B13),"01 Ene","02 Feb","03 Mar","04 Abr","05 May","06 Jun","07 Jul","08 Ago","09 Sep","10 Oct","11 Nov","12 Dic") -> 01 Ene | D13: ="T"&ROUNDUP(MONTH(B13)/3,0) -> T1 | E13: =INDEX(Productos!$B$2:$B$11,MATCH(Datos_Ventas!D13,Productos!$A$2:$A$11,0)) -> Aceite Omega | F13: =INDEX(Productos!$C$2:$C$11,MATCH(Datos_Ventas!D13,Productos!$A$2:$A$11,0)) -> Suplementos | G13: =INDEX(Clientes!$B$2:$B$11,MATCH(Datos_Ventas!C13,Clientes!$A$2:$A$11,0)) -> Veterinaria Sur | H13: =INDEX(Clientes!$C$2:$C$11,MATCH(Datos_Ventas!C13,Clientes!$A$2:$A$11,0)) -> Especializado | I13: =INDEX(Clientes!$D$2:$D$11,MATCH(Datos_Ventas!C13,Clientes!$A$2:$A$11,0)) -> Godoy Cruz | J13: =Datos_Ventas!E13 -> 13 | K13: =Datos_Ventas!F13 -> 5350 | L13: =Datos_Ventas!G13 -> 69550 | M13: =J13*INDEX(Productos!$D$2:$D$11,MATCH(Datos_Ventas!D13,Productos!$A$2:$A$11,0)) -> 40300 | N13: =L13-M13 -> 29250 | O13: =K13/INDEX(Productos!$E$2:$E$11,MATCH(Datos_Ventas!D13,Productos!$A$2:$A$11,0))-1 -> -0.044642857 | P13: =SUBTOTAL(103,A13) -> 1
... A397: =Datos_Ventas!A397 -> 420 | B397: =Datos_Ventas!B397 -> 46293 | C397: =CHOOSE(MONTH(B397),"01 Ene","02 Feb","03 Mar","04 Abr","05 May","06 Jun","07 Jul","08 Ago","09 Sep","10 Oct","11 Nov","12 Dic") -> 09 Sep | D397: ="T"&ROUNDUP(MONTH(B397)/3,0) -> T3 | E397: =INDEX(Productos!$B$2:$B$11,MATCH(Datos_Ventas!D397,Productos!$A$2:$A$11,0)) -> Snack Dental | F397: =INDEX(Productos!$C$2:$C$11,MATCH(Datos_Ventas!D397,Productos!$A$2:$A$11,0)) -> Snacks | G397: =INDEX(Clientes!$B$2:$B$11,MATCH(Datos_Ventas!C397,Clientes!$A$2:$A$11,0)) -> Kiosco La Esquina | H397: =INDEX(Clientes!$C$2:$C$11,MATCH(Datos_Ventas!C397,Clientes!$A$2:$A$11,0)) -> Minorista | I397: =INDEX(Clientes!$D$2:$D$11,MATCH(Datos_Ventas!C397,Clientes!$A$2:$A$11,0)) -> Godoy Cruz | J397: =Datos_Ventas!E397 -> 20 | K397: =Datos_Ventas!F397 -> 2970 | L397: =Datos_Ventas!G397 -> 59400 | M397: =J397*INDEX(Productos!$D$2:$D$11,MATCH(Datos_Ventas!D397,Productos!$A$2:$A$11,0)) -> 36000 | N397: =L397-M397 -> 23400 | O397: =K397/INDEX(Productos!$E$2:$E$11,MATCH(Datos_Ventas!D397,Productos!$A$2:$A$11,0))-1 -> -0.071875 | P397: =SUBTOTAL(103,A397) -> 1

Sheet Calc_Dashboard
A1: Cálculos de soporte del Dashboard (no editar · todo responde a los segmentadores vía la columna Visible de tblBaseDash)
A3: Ventas | B3: =SUMIFS(bMonto,bVis,1) -> 53694490
A4: Costo de mercadería | B4: =SUMIFS(bCosto,bVis,1) -> 32984500 | C4: Cantidad × Productos[Costo_Unitario]
A5: Margen bruto | B5: =B3-B4 -> 20709990
A6: Margen bruto % | B6: =IF(B3=0,0,B5/B3) -> 0.38570047
A7: Gastos operativos % (supuesto) | B7: =Simulación_Escenarios!$C$7 -> 0.15 | C7: Fuente: hoja Simulación_Escenarios (supuesto del Módulo 4)
A8: Gastos operativos | B8: =B3*B7 -> 8054173.5
A9: Utilidad antes de impuestos | B9: =B5-B8 -> 12655816
A10: Tasa de impuesto (supuesto) | B10: =Simulación_Escenarios!$C$8 -> 0.3 | C10: Fuente: hoja Simulación_Escenarios
A11: Impuesto | B11: =MAX(0,B9)*B10 -> 3796744.9
A12: Margen neto | B12: =B9-B11 -> 8859071.6
A13: Margen neto % | B13: =IF(B3=0,0,B12/B3) -> 0.16499033
A14: Transacciones | B14: =COUNTIFS(bVis,1) -> 396
A15: Unidades | B15: =SUMIFS(bCant,bVis,1) -> 8371
A16: Ticket promedio | B16: =IF(B14=0,0,B3/B14) -> 135592.15
A17: Último mes con ventas (n°) | B17: =MAX(H25:H33) -> 9
A18: Ventas último mes | B18: =IF(B17=0,0,INDEX(D25:D33,B17)) -> 6510070
A19: Ventas mes anterior | B19: =IF(B17<=1,0,INDEX(D25:D33,B17-1)) -> 6028750
A20: Crecimiento vs mes anterior | B20: =IF(B19=0,0,B18/B19-1) -> 0.079837446 | C20: YoY no calculable: el modelo sólo tiene datos de 2026
A21: Unidades por venta | B21: =IF(B14=0,0,B15/B14) -> 21.138889
A24: N° | B24: Mes | C24: Mes corto | D24: Ventas | E24: Costo | F24: Margen bruto | G24: Margen % | H24: N° si tiene ventas
A25: 1 | B25: 01 Ene | C25: Ene | D25: =SUMIFS(bMonto,bVis,1,bMes,B25) -> 4904630 | E25: =SUMIFS(bCosto,bVis,1,bMes,B25) -> 2974800 | F25: =D25-E25 -> 1929830 | G25: =IF(D25=0,0,F25/D25) -> 0.39347107 | H25: =IF(D25>0,A25,0) -> 1
A26: 2 | B26: 02 Feb | C26: Feb | D26: =SUMIFS(bMonto,bVis,1,bMes,B26) -> 5020900 | E26: =SUMIFS(bCosto,bVis,1,bMes,B26) -> 3031600 | F26: =D26-E26 -> 1989300 | G26: =IF(D26=0,0,F26/D26) -> 0.39620387 | H26: =IF(D26>0,A26,0) -> 2
A27: 3 | B27: 03 Mar | C27: Mar | D27: =SUMIFS(bMonto,bVis,1,bMes,B27) -> 7919930 | E27: =SUMIFS(bCosto,bVis,1,bMes,B27) -> 4933200 | F27: =D27-E27 -> 2986730 | G27: =IF(D27=0,0,F27/D27) -> 0.37711571 | H27: =IF(D27>0,A27,0) -> 3
A28: 4 | B28: 04 Abr | C28: Abr | D28: =SUMIFS(bMonto,bVis,1,bMes,B28) -> 3734780 | E28: =SUMIFS(bCosto,bVis,1,bMes,B28) -> 2215800 | F28: =D28-E28 -> 1518980 | G28: =IF(D28=0,0,F28/D28) -> 0.40671204 | H28: =IF(D28>0,A28,0) -> 4
A29: 5 | B29: 05 May | C29: May | D29: =SUMIFS(bMonto,bVis,1,bMes,B29) -> 7201860 | E29: =SUMIFS(bCosto,bVis,1,bMes,B29) -> 4485100 | F29: =D29-E29 -> 2716760 | G29: =IF(D29=0,0,F29/D29) -> 0.37723033 | H29: =IF(D29>0,A29,0) -> 5
A30: 6 | B30: 06 Jun | C30: Jun | D30: =SUMIFS(bMonto,bVis,1,bMes,B30) -> 6351740 | E30: =SUMIFS(bCosto,bVis,1,bMes,B30) -> 3960200 | F30: =D30-E30 -> 2391540 | G30: =IF(D30=0,0,F30/D30) -> 0.3765173 | H30: =IF(D30>0,A30,0) -> 6
A31: 7 | B31: 07 Jul | C31: Jul | D31: =SUMIFS(bMonto,bVis,1,bMes,B31) -> 6021830 | E31: =SUMIFS(bCosto,bVis,1,bMes,B31) -> 3709600 | F31: =D31-E31 -> 2312230 | G31: =IF(D31=0,0,F31/D31) -> 0.38397464 | H31: =IF(D31>0,A31,0) -> 7
A32: 8 | B32: 08 Ago | C32: Ago | D32: =SUMIFS(bMonto,bVis,1,bMes,B32) -> 6028750 | E32: =SUMIFS(bCosto,bVis,1,bMes,B32) -> 3563300 | F32: =D32-E32 -> 2465450 | G32: =IF(D32=0,0,F32/D32) -> 0.40894879 | H32: =IF(D32>0,A32,0) -> 8
A33: 9 | B33: 09 Sep | C33: Sep | D33: =SUMIFS(bMonto,bVis,1,bMes,B33) -> 6510070 | E33: =SUMIFS(bCosto,bVis,1,bMes,B33) -> 4110900 | F33: =D33-E33 -> 2399170 | G33: =IF(D33=0,0,F33/D33) -> 0.36853214 | H33: =IF(D33>0,A33,0) -> 9
A36: Categoría | B36: Ventas | C36: Margen bruto | D36: Margen % | E36: Clave orden | H36: Rank | I36: Categoría (orden ventas) | J36: Ventas | K36: Margen % | L36: Participación
A37: Accesorios | B37: =SUMIFS(bMonto,bVis,1,bCat,A37) -> 7633470 | C37: =SUMIFS(bMargen,bVis,1,bCat,A37) -> 3566870 | D37: =IF(B37=0,0,C37/B37) -> 0.46726718 | E37: =B37+ROW()/1000 -> 7633470 | H37: 1 | I37: =INDEX($A$37:$A$41,MATCH(LARGE($E$37:$E$41,H37),$E$37:$E$41,0)) -> Alimentos | J37: =INDEX($B$37:$B$41,MATCH(I37,$A$37:$A$41,0)) -> 28348650 | K37: =INDEX($D$37:$D$41,MATCH(I37,$A$37:$A$41,0)) -> 0.3337778 | L37: =IF($B$3=0,0,J37/$B$3) -> 0.52796199
A38: Alimentos | B38: =SUMIFS(bMonto,bVis,1,bCat,A38) -> 28348650 | C38: =SUMIFS(bMargen,bVis,1,bCat,A38) -> 9462150 | D38: =IF(B38=0,0,C38/B38) -> 0.3337778 | E38: =B38+ROW()/1000 -> 28348650 | H38: 2 | I38: =INDEX($A$37:$A$41,MATCH(LARGE($E$37:$E$41,H38),$E$37:$E$41,0)) -> Accesorios | J38: =INDEX($B$37:$B$41,MATCH(I38,$A$37:$A$41,0)) -> 7633470 | K38: =INDEX($D$37:$D$41,MATCH(I38,$A$37:$A$41,0)) -> 0.46726718 | L38: =IF($B$3=0,0,J38/$B$3) -> 0.14216487
A39: Higiene | B39: =SUMIFS(bMonto,bVis,1,bCat,A39) -> 6798920 | C39: =SUMIFS(bMargen,bVis,1,bCat,A39) -> 2865720 | D39: =IF(B39=0,0,C39/B39) -> 0.42149636 | E39: =B39+ROW()/1000 -> 6798920 | H39: 3 | I39: =INDEX($A$37:$A$41,MATCH(LARGE($E$37:$E$41,H39),$E$37:$E$41,0)) -> Higiene | J39: =INDEX($B$37:$B$41,MATCH(I39,$A$37:$A$41,0)) -> 6798920 | K39: =INDEX($D$37:$D$41,MATCH(I39,$A$37:$A$41,0)) -> 0.42149636 | L39: =IF($B$3=0,0,J39/$B$3) -> 0.1266223
A40: Snacks | B40: =SUMIFS(bMonto,bVis,1,bCat,A40) -> 5694990 | C40: =SUMIFS(bMargen,bVis,1,bCat,A40) -> 2492190 | D40: =IF(B40=0,0,C40/B40) -> 0.43761095 | E40: =B40+ROW()/1000 -> 5694990 | H40: 4 | I40: =INDEX($A$37:$A$41,MATCH(LARGE($E$37:$E$41,H40),$E$37:$E$41,0)) -> Snacks | J40: =INDEX($B$37:$B$41,MATCH(I40,$A$37:$A$41,0)) -> 5694990 | K40: =INDEX($D$37:$D$41,MATCH(I40,$A$37:$A$41,0)) -> 0.43761095 | L40: =IF($B$3=0,0,J40/$B$3) -> 0.10606284
A41: Suplementos | B41: =SUMIFS(bMonto,bVis,1,bCat,A41) -> 5218460 | C41: =SUMIFS(bMargen,bVis,1,bCat,A41) -> 2323060 | D41: =IF(B41=0,0,C41/B41) -> 0.44516198 | E41: =B41+ROW()/1000 -> 5218460 | H41: 5 | I41: =INDEX($A$37:$A$41,MATCH(LARGE($E$37:$E$41,H41),$E$37:$E$41,0)) -> Suplementos | J41: =INDEX($B$37:$B$41,MATCH(I41,$A$37:$A$41,0)) -> 5218460 | K41: =INDEX($D$37:$D$41,MATCH(I41,$A$37:$A$41,0)) -> 0.44516198 | L41: =IF($B$3=0,0,J41/$B$3) -> 0.097187998
A42: Menor margen % entre categorías con ventas | B42: =_xlfn.MINIFS(D37:D41,B37:B41,">0") -> 0.3337778 | C42: =IF(B106=0,"-",INDEX(A37:A41,MATCH(B42,D37:D41,0))) -> Alimentos
A43: Margen $ de la categoría líder | B43: =INDEX(C37:C41,MATCH(I37,A37:A41,0)) -> 9462150 | C43: =IF($B$3-J37=0,0,($B$5-B43)/($B$3-J37)) -> 0.4437746 | D43: ← margen % del resto del portafolio
A46: Ciudad | B46: Ventas | C46: Margen bruto | D46: Margen % | E46: Desvío vs prom. (p.p.) | F46: Clave orden | H46: Rank | I46: Ciudad (orden margen) | J46: Desvío p.p. | K46: Margen % | L46: Ventas
A47: Godoy Cruz | B47: =SUMIFS(bMonto,bVis,1,bCiu,A47) -> 8787320 | C47: =SUMIFS(bMargen,bVis,1,bCiu,A47) -> 3412520 | D47: =IF(B47=0,0,C47/B47) -> 0.38834593 | E47: =IF(B47=0,0,(D47-$B$6)*100) -> 0.26454654 | F47: =IF(B47=0,-1000,E47)+ROW()/1000000 -> 0.26459354 | H47: 1 | I47: =INDEX($A$47:$A$53,MATCH(LARGE($F$47:$F$53,H47),$F$47:$F$53,0)) -> Maipú | J47: =INDEX($E$47:$E$53,MATCH(I47,$A$47:$A$53,0)) -> 1.9029198 | K47: =INDEX($D$47:$D$53,MATCH(I47,$A$47:$A$53,0)) -> 0.40472967 | L47: =INDEX($B$47:$B$53,MATCH(I47,$A$47:$A$53,0)) -> 3582070
...

Sheet Análisis_IA
B2: Análisis asistido por IA · Prueba de estrés de los insights del Dashboard
B3: Registro de cómo se usó la IA para generar hipótesis y cómo cada una se validó (o descartó) con los datos del modelo. Las hipótesis de la columna E son un primer borrador generado con un asistente de IA (Claude). Para cumplir la consigna, pegá cada prompt de la columna D en ChatGPT, copiá su respuesta en la columna I y ajustá las columnas E–H si ChatGPT propone hipótesis distintas.
B5: Metodología
B6: 1. Se leyeron los hallazgos del Dashboard (KPIs, cascada, dispersión, ciudades, tendencia) sin filtros.
B7: 2. Se describió cada hallazgo a la IA con números concretos y se pidieron hipótesis de negocio y cómo validarlas.
B8: 3. Cada hipótesis se contrastó con una fórmula sobre el modelo (columna G, en vivo) y con los segmentadores del Dashboard.
B9: 4. Sólo las hipótesis sostenidas pasaron a las "Notas de Análisis" del Dashboard; las descartadas quedan documentadas acá.
B11: N° | C11: Hallazgo del Dashboard | D11: Prompt enviado a la IA | E11: Hipótesis propuestas por la IA | F11: Validación con los datos | G11: Dato de control (fórmula en vivo) | H11: Resultado | I11: Respuesta textual de ChatGPT (pegar)
B12: 1 | C12: Alimentos genera ~53% de las ventas con margen bruto de 33,4%, contra ~44,4% del resto. El costo de mercadería absorbe el 61% de las ventas. | D12: Tengo un dashboard de una distribuidora de productos para mascotas en Mendoza. La categoría Alimentos genera el 53% de las ventas pero tiene un margen bruto de 33% contra 45% del resto, y en la cascada el costo de mercadería se lleva el 61% de las ventas. ¿Qué hipótesis de negocio podrían explicar esto y cómo las validaría con datos? | E12: a) Efecto mix: el alimento es un producto "commodity" cuyo precio el cliente compara. b) Mayor poder de negociación de los proveedores de alimento. c) Alimentos se usa como producto gancho con descuentos. | F12: Desvío medio de precio vs lista en Alimentos ≈ +0,3% (no hay descuentos extra) → c) se descarta. El margen de lista de los alimentos ya es ~33% → el margen bajo es estructural: a) y b) se sostienen. | G12: =AVERAGEIFS(Base_Dashboard!$O$2:$O$397,Base_Dashboard!$F$2:$F$397,"Alimentos") -> 0.0027416947 | H12: a) y b) sostenidas · c) descartada → Nota 1
B13: 2 | C13: El precio cobrado varía ±8% respecto de la lista y no se relaciona con la cantidad (r ≈ 0,02). Hay 18 ventas de menos de 10 u. con más de 5% de descuento. | D13: En un gráfico de dispersión de unidades por venta vs. desvío del precio respecto de la lista, la correlación es casi nula (r = 0,02) y hay 18 ventas de menos de 10 unidades con más de 5% de descuento. ¿Qué podría explicar descuentos que no dependen del volumen? ¿Qué riesgo tiene para el margen? | E13: a) Descuentos discrecionales del vendedor. b) Acuerdos comerciales por cliente, no por pedido. c) Errores de carga de precios. d) Promociones puntuales por fecha. | F13: Correlación global ≈ 0 → no hay política por volumen: a) sostenida. Los desvíos se reparten en todas las categorías y ciudades (entre −1,1% y +0,8%): b) y d) quedan a revisar por cliente y fecha. c) no se puede validar sin el log de facturación. | G13: =CORREL(Base_Dashboard!$J$2:$J$397,Base_Dashboard!$O$2:$O$397) -> 0.022854337 | H13: a) sostenida · b), d) a revisar → Nota 2
B14: 3 | C14: Mendoza (capital) factura ~35% del total pero tiene el margen más bajo (37,1% vs 38,6% promedio). | D14: En mi dashboard la ciudad de Mendoza concentra el 35% de las ventas pero tiene el menor margen bruto (37,1% vs 38,6% promedio). ¿Qué hipótesis podrían explicarlo? | E14: a) Más competencia urbana que obliga a descontar. b) Mix de productos con más Alimentos (menor margen). c) Clientes más grandes con mejores condiciones. | F14: Desvío medio de precio en Mendoza ≈ −0,5% vs −0,3% general → a) no explica la brecha. Alimentos pesa 62,6% de las ventas en Mendoza vs 47,5% en el resto → b) sostenida. c) a validar por cliente. | G14: =SUMIFS(Base_Dashboard!$L$2:$L$397,Base_Dashboard!$I$2:$I$397,"Mendoza",Base_Dashboard!$F$2:$F$397,"Alimentos")/SUMIFS(Base_Dashboard!$L$2:$L$397,Base_Dashboard!$I$2:$I$397,"Mendoza") -> 0.62551125 | H14: b) sostenida · a) descartada → Nota 3
B15: 4 | C15: Marzo es el pico ($7,9 M) y abril el valle ($3,7 M, −53%). | D15: Mis ventas mensuales muestran un pico en marzo ($7,9 M) y una caída del 53% en abril ($3,7 M). ¿Qué hipótesis de negocio explican esta estacionalidad y qué datos miraría para confirmarlas? | E15: a) Abril tiene menos días hábiles (feriados de Semana Santa). b) Compras anticipadas de stock en marzo (inicio de otoño/clases). c) Caída de transacciones más que de ticket. | F15: Abril tiene 30 días vs 31 (−3%): a) explica muy poco. Las transacciones caen de 51 a 35 (−31%) → c) sostenida. En marzo el segmento Minorista duplica su promedio → b) sostenida para Minorista. | G15: =COUNTIFS(Base_Dashboard!$C$2:$C$397,"04 Abr")/COUNTIFS(Base_Dashboard!$C$2:$C$397,"03 Mar")-1 -> -0.31372549 | H15: b) y c) sostenidas · a) parcial → Nota 4
B16: 5 | C16: Prueba de la consigna: "los costos logísticos subieron 12% mientras el margen cayó 5%". | D16: Tengo un gráfico de cascada que muestra que los costos logísticos subieron un 12% mientras el margen cayó un 5%. ¿Qué hipótesis de negocio podrían explicar esto? | E16: a) Suba de combustible/tarifas de flete. b) Más pedidos chicos (más envíos por peso vendido). c) Envíos a zonas más lejanas. d) Devoluciones o envíos urgentes. | F16: El modelo no tiene costos logísticos, por lo que no se puede validar. Sí se puede medir el proxy de b): unidades por venta (control a la derecha). Recomendación: agregar costo de flete por pedido a VentasHechos. | G16: =SUM(Base_Dashboard!$J$2:$J$397)/COUNT(Base_Dashboard!$A$2:$A$397) -> 21.138889 | H16: No validable con el modelo actual (pendiente)
